Workbook

Sheet Read Me
A1: PILLAR 4 - US STOCK NOTES
A3: What this is | B3: Every comment Claude has written about each stock in the US dashboard, kept in one place so you and Dad can re-read the reasoning instead of asking the same question twice.
A4: Generated | B4: 2026-09-19
A5: Objective on record | B5: SL-P4: 100% capital gain over five years, 2026-2030 (about 15% a year).
A7: SHEET | B7: WHAT IS IN IT
A8: Stock Index | B8: One row per ticker: a plain-English line on WHAT THE COMPANY DOES, then when it was founded, its headquarters, employee count, and separate OPERATIONS and VISION notes - followed by group, whether you hold it, shares, cost, budget, last price and the most recent thing Claude said about it. Start here.
A9: Comment Log | B9: Executive summaries, one row per stock per week (Monday-Sunday). GREEN text = something positive, RED text = a risk or negative view, bold RED FLAG = urgent warning. The View column gives the week's overall tilt at a glance.
A10: Full Log | B10: The complete unabridged archive - every individual comment with its exact date, for when the summary is not enough.
A11: Dashboard Notes | B11: The dated technical notes stored inside the dashboard itself - data conflicts, earnings dates, warnings, what was verified and what was not. Longer and more detailed than the chat comments.
A12: Our Notes | B12: YOURS. Claude never overwrites this sheet - it is read back and carried forward on every rebuild. Put your own observations, Dad's notes, and decisions here.
A13: Follow-ups | B13: Open items Claude is carrying: unanswered offers, data to fix, earnings to watch.
A15: HOW TO LOOK UP ONE STOCK
A16: 1 | B16: Go to the Comment Log sheet.
A17: 2 | B17: Click the small arrow in the Ticker header (row 1, column A).
A18: 3 | B18: Untick "Select All", tick just the ticker you want, press OK.
A19: 4 | B19: Every comment about that stock, oldest to newest, is now on screen.
A20: 5 | B20: To clear it, click the arrow again and tick "Select All".
A22: IMPORTANT LIMITS
A23: Not advice | B23: These are analytical comments, not licensed investment advice. Every order is placed by Salee.
A24: Comments age | B24: A comment is a snapshot of what was true and known on its date. A buy case from three weeks ago may have been overtaken by an earnings report. Always check the date column.
A25: Prices are closes | B25: Prices in the Stock Index come from the dashboard and are closing prices with a stated date, not live quotes.
A26: Coverage | B26: Comments were mined from the chat history of the Jul 20 - Aug 7 2026 session plus the full git history of the dashboard. Anything said before that session is not captured.

Sheet Stock Index
A1: Ticker | B1: Company | C1: What the company does | D1: Founded | E1: Headquarters | F1: Employees | G1: Operations | H1: Vision | I1: Group | J1: Held | K1: Shares | L1: Cost (USD) | M1: Budget (USD) | N1: Last close (USD) | O1: Price date | P1: Comments | Q1: First comment | R1: Last comment | S1: Most recent comment
A2: AMZN | B2: Amazon | C2: Online shopping giant, and the world's largest cloud-computing provider (AWS). | D2: 1994 | E2: Washington, United States | F2: 1,576,000 | G2: Runs online and physical shops in North America and other countries, plus a large computing-rental arm and its own devices such as Kindle and Echo. | H2: To sell consumer goods, advertising and subscriptions through online and physical stores in North America and internationally. | I2: Hyperscalers & Model Owners | J2: YES | K2: 209 | L2: 48600.75 | M2: 48000 | N2: 251.19 | O2: 2026-09-17 | P2: =COUNTIF('Full Log'!$A:$A,$A2) | Q2: 2026-07-20 | R2: 2026-09-17 | S2: Your AMZN buy is logged. 7 shares @ $285.3599 (limit 285.50, order 65487), $1,997.52 + $8.56 fees = $2,006.08. You now hold 209 shares at an average cost of $232.54, worth $59,360 — up 22.1%. Budget left in the Amazon sleeve: $1,399.25, so that position is now essentially full.
A3: GOOGL | B3: Alphabet | C3: Google search and YouTube advertising, plus Google Cloud and Waymo self-driving cars. | D3: 1998 | E3: California, United States | F3: 190,820 | G3: Runs search, advertising, phone software, video and email services across the Americas, Europe, Africa, the Middle East and Asia, plus a computing-rental arm. | H3: To offer a wide range of internet products and platforms, grouped into its main services, its computing-rental business and smaller ventures. | I3: Hyperscalers & Model Owners | J3: YES | K3: 217 | L3: 59475.92 | M3: 78000 | N3: 347.33 | O3: 2026-09-17 | P3: =COUNTIF('Full Log'!$A:$A,$A3) | Q3: 2026-07-20 | R3: 2026-09-18 | S3: First — a useful discovery about your broker. I checked whether the "Current Price" column in your POEMS screen was a live intraday quote or the official close, because it matters for the dashboard's integrity. I tested four names against an independent source: MSFT $487.65, META $590.24, TSM $406.11, GOOGL $373.51 — all four matched to the cent. That column is the official close. It means your POEMS screenshot is a legitimate price source for the whole held book, and future updates get much faster.
A4: META | B4: Meta Platforms | C4: Facebook, Instagram and WhatsApp — sells advertising to their billions of users. | D4: 2004 | E4: California, United States | F4: 78,865 | G4: Runs Facebook, Instagram, WhatsApp and Messenger, plus a division making virtual-reality headsets and smart glasses, serving users in most world regions. | H4: To build products that let people connect and share with friends and family through phones, computers, headsets and smart glasses. | I4: Hyperscalers & Model Owners | J4: YES | K4: 59.5 | L4: 39239.51 | M4: 52000 | N4: 682.31 | O4: 2026-09-17 | P4: =COUNTIF('Full Log'!$A:$A,$A4) | Q4: 2026-07-20 | R4: 2026-09-17 | S4: Your six buys from last night are in. FN 3 sh @ $532.00, LITE 2 sh @ $854.68, META 3.5 sh @ $583.24, COHR 4 sh @ $330.00, AAOI 10 sh @ $133.00 — $8,039.48 total. Every fill price was reverse-engineered from the cash amounts, and they all came out to clean round limit prices with a flat $8.56 commission, which is exactly what POEMS charges. Your new cost basis of $560,431.70 matches the POEMS statement to the cent.
A5: MSFT | B5: Microsoft | C5: Windows and Office software, Azure cloud computing, and a large stake in OpenAI. | D5: 1975 | E5: Washington, United States | F5: 223,000 | G5: Sells office and business software, rented computing power, Windows, game consoles and search advertising to people and companies worldwide. | H5: To develop and support a broad set of technology products and services for individuals and businesses around the world. | I5: Hyperscalers & Model Owners | J5: YES | K5: 117 | L5: 52878.96 | M5: 58000 | N5: 497.75 | O5: 2026-09-17 | P5: =COUNTIF('Full Log'!$A:$A,$A5) | Q5: 2026-07-20 | R5: 2026-09-17 | S5: - VEEV's return-on-capital reads 176% on one source and 31% on another. I stored the conservative 31.44%. The 176% is a maths artifact — Veeva has almost no debt and a tiny capital base, so the ratio explodes. Don't read it as "six times better than Microsoft."
A6: AMBA | B6: Ambarella | I6: AI Chips & Chip Design | N6: 64.33 | O6: 2026-09-15 | P6: =COUNTIF('Full Log'!$A:$A,$A6) | Q6: 2026-08-19 | R6: 2026-09-09 | S6: Sep 9, 2026: AMBARELLA (AMBA) ADDED TO THE BOARD AS AN UNFUNDED WATCH ROW WITH A REJECT VERDICT, at Salee's instruction to record the research rather than repeat it. Group 1, budget 0, nothing bought. Edge-AI vision SoCs, 50m+ AI units installed, price 63.48 and 34.4% below its 96.69 high. ⚠️ REJECTED ON THREE COUNTS: revenue growth decelerating four quarters running to 13.2%; GAAP loss-making in each of the last five quarters with trailing net income -56.32m; and stock compensation running at 21% of revenue, larger than the entire non-GAAP profit. Add a single distributor at 60.2% of revenue and a forward P/E of 71.49. It fails both screens Salee approved this week - the under-15% growth cut of Sep 7 and the loss-making cut of Sep 8.
A7: AMD | B7: Advanced Micro Devices | C7: Designs computer processors and AI chips — Nvidia's main challenger. | D7: 1969 | E7: California, United States | F7: 31,000 | G7: Designs chips sold internationally through three business lines: data centres, personal computers and gaming, and equipment with chips built in. | H7: To supply processors, graphics chips and artificial-intelligence hardware for business and consumer computing worldwide. | I7: AI Chips & Chip Design | J7: YES | K7: 55 | L7: 13789.22 | M7: 24000 | N7: 545.09 | O7: 2026-09-17 | P7: =COUNTIF('Full Log'!$A:$A,$A7) | Q7: 2026-07-21 | R7: 2026-09-18 | S7: > Conviction: High — but on *valuation and position discipline*, not on "NVDA always goes up." > > Horizon: Long (2+ years) — this fits the 2026–2030 doubling objective. > > What would change my mind: (1) Aug 26 earnings guiding below ~$91B or gross margin slipping under 73% — that would say the pricing power is cracking; (2) any sign the hyperscalers are cutting 2027 capex plans; (3) NVDA rising above ~$260 before earnings, which would put it at a forward multiple where the cheapness argument stops working; (4) SpaceX or another marquee customer publicly dual-sourcing to AMD or in-house silicon.
A8: ARM | B8: Arm Holdings | C8: Licenses the chip blueprints used inside nearly every smartphone in the world. | D8: 1990 | E8: United Kingdom | F8: 9,584 | G8: Licenses chip blueprints rather than making chips, serving chipmakers, device makers and computing-rental firms for phones, cars and data centres. | H8: To research, develop and license chip designs, software and tools that other companies use to build their own chips. | I8: AI Chips & Chip Design | N8: 241.83 | O8: 2026-09-15 | P8: =COUNTIF('Full Log'!$A:$A,$A8) | Q8: 2026-07-21 | R8: 2026-09-18 | S8: Portfolio now: $560,432 cost, $683,857 market value, +$123,426 (+22.02%). A strong day across the board — 109 of 112 names repriced, and the tone was risk-on: PLTR +29%, AAOI +19%, ARM +17%, FN +16%, your own AMD +7% and AVGO +6.6%.
A9: AVGO | B9: Broadcom | C9: Custom AI chips and networking parts, plus a large enterprise software business. | D9: 1961 | E9: California, United States | F9: 33,000 | G9: Supplies chips and business software internationally through two arms: semiconductor products and infrastructure software. | H9: To design and supply the chips and software that run company networks, data centres, telephone systems and broadband. | I9: AI Chips & Chip Design | J9: YES | K9: 88.5 | L9: 30125.18 | M9: 50000 | N9: 347.3 | O9: 2026-09-17 | P9: =COUNTIF('Full Log'!$A:$A,$A9) | Q9: 2026-07-23 | R9: 2026-09-16 | S9: Portfolio now: $560,432 cost, $683,857 market value, +$123,426 (+22.02%). A strong day across the board — 109 of 112 names repriced, and the tone was risk-on: PLTR +29%, AAOI +19%, ARM +17%, FN +16%, your own AMD +7% and AVGO +6.6%.
A10: CDNS | B10: Cadence Design Systems | C10: The software that engineers use to design computer chips. | D10: 1988 | E10: California, United States | F10: 13,800 | G10: Sells software, testing hardware and ready-made circuit designs to electronics and chip makers, and works in partnership with NVIDIA. | H10: To provide the software, hardware and design building blocks that engineers use to design computer chips and electronic systems. | I10: AI Chips & Chip Design | J10: YES | K10: 12 | L10: 3918.01 | N10: 280.76 | O10: 2026-09-17 | P10: =COUNTIF('Full Log'!$A:$A,$A10) | Q10: 2026-07-21 | R10: 2026-09-17 | S10: The practical cadence. Fundamentals refresh when a company files, not on a clock. For your US names that means roughly four times a year each. The revenue and EPS you'd read off TradingView on a Tuesday are identical to Monday's unless that company reported in between. So it's an event-driven feed, not a daily one.
A11: MCHP | B11: Microchip Technology | C11: Microcontrollers and analog chips for cars, factory equipment and data centres. | D11: 1989 | E11: Arizona, United States | F11: 17,900 | G11: Makes and sells small control chips across the Americas, Europe and Asia through two arms: semiconductor products and technology licensing. | H11: To develop, make and sell smart, connected and secure control chips that sit inside other companies' equipment. | I11: AI Chips & Chip Design | N11: 71.49 | O11: 2026-09-15 | P11: =COUNTIF('Full Log'!$A:$A,$A11) | Q11: 2026-08-09 | R11: 2026-08-09 | S11: Aug 8 addition: MCHP (Microchip Technology, NASDAQ) added to Computing Chips at the Aug 7, 2026 close 84.69, UP 13.89% that day, stamp 'At close: Aug 7, 2026, 4:00 PM EDT', second-sourced by MarketBeat. Watchlist only - no position, no budget. Microchip makes microcontrollers, analog and connectivity chips for cars, industry, aerospace/defence and data centres, and is RECOVERING from a deep inventory-correction downcycle. Q1 FY2027 (ended Jun 30, reported Aug 6) was a clear beat and the trigger for the pop: net sales 1.485B (+38% YoY, +13% QoQ), GAAP EPS 0.37 (vs a loss a year ago), non-GAAP EPS 0.76; Q2 guidance strong (~1.6B, +41% YoY); inventory days improving (185->175); PCIe Gen 6 / data-centre commentary cited. Pays a ~2.15% dividend (0.455/qtr). KEY VALUATION NOTE: trailing P/E 124.83 and payout ratio 268% look alarming but are DISTORTED by trough earnings during the downturn - ...
A12: MPWR | B12: Monolithic Power | C12: Power-management chips that feed clean, steady voltage to AI processors. | D12: 1997 | E12: Florida, United States | F12: 4,501 | G12: Designs power-management chips used in data centre servers, cars, appliances and networks, sold through distributors in China, Taiwan, Korea, Europe, the US and Japan. | H12: To supply the semiconductor parts that convert and control electrical power inside electronic systems. | I12: AI Chips & Chip Design | N12: 1142.46 | O12: 2026-09-15 | P12: =COUNTIF('Full Log'!$A:$A,$A12) | Q12: 2026-07-21 | R12: 2026-09-12 | S12: The picture got further away, not closer. Amazon jumped 15% and Monolithic Power 10.6% overnight — both blew straight through your limits. Google added 4.6%. Nothing moved toward you except Micron and Coinbase, and both are still short of the mark. ISRG remains the nearest at 5.6%, and it's drifting your way rather than away.
A13: MRVL | B13: Marvell Technology | C13: Custom data-centre chips that move data between AI servers. | D13: 1995 | E13: Delaware, United States | F13: 7,480 | G13: Designs data-centre and networking chips, with operations in the United States, Argentina, China, India, Israel, Japan, Singapore, South Korea, Taiwan and Vietnam. | H13: To supply the chips that move and store data from the heart of large data centres out to the edge of networks. | I13: AI Chips & Chip Design | J13: YES | K13: 48.5 | L13: 7872.66 | M13: 21000 | N13: 240.76 | O13: 2026-09-17 | P13: =COUNTIF('Full Log'!$A:$A,$A13) | Q13: 2026-07-22 | R13: 2026-09-16 | S13: ⚠ But I have to challenge your own note, because you wrote two things that conflict. Your price limits say "buy RKLB." Your *new valuation measures* — Price/FCF ≤ 10× and EV/EBITDA < 10 — say buy none of these. RKLB has negative free cash flow and no meaningful EBITDA; it fails both screens by a mile. So do CRDO, MRVL, and ONDS. Those deep-value gates (P/FCF ≤10, EV/EBITDA <10) are built for mature cash machines — they will *permanently* exclude every growth/space/AI name on this list. You can run a price-limit discipline *or* a hard value screen, but not both on the same tickers. Decide which game each name is playing before you buy, or you'll never pull the trigger on anything.
A14: NVDA | B14: NVIDIA | C14: Makes the GPU chips that almost all AI computing runs on. | D14: 1993 | E14: California, United States | F14: 42,000 | G14: Sells computing and graphics chips through two arms, with operations in the United States, Taiwan, China, Hong Kong and Europe. | H14: To operate as a company that supplies the computing equipment whole data centres use for artificial intelligence. | I14: AI Chips & Chip Design | J14: YES | K14: 420 | L14: 79380.28 | M14: 95000 | N14: 219.34 | O14: 2026-09-17 | P14: =COUNTIF('Full Log'!$A:$A,$A14) | Q14: 2026-07-20 | R14: 2026-09-19 | S14: - SpaceX went exclusive. Announced Aug 5: SpaceX is building its "Starmind" AI system *exclusively* on NVIDIA chips (Vera CPUs, Rubin GPUs). Musk called the architecture "the best." SpaceX targets 10 gigawatts of computing power by end-2027 and says it'll take "a very significant percentage" of NVIDIA's GPUs next year. This is a brand-new customer at a scale that barely existed six months ago.
A15: QCOM | B15: Qualcomm | C15: Smartphone processors and modems, expanding into cars and AI laptops. | D15: 1985 | E15: California, United States | F15: 52,000 | G15: Runs three arms worldwide: chip products, patent licensing and start-up investing, plus government services and data-centre products. | H15: To develop and commercialise the basic technologies that the wireless telephone industry depends on. | I15: AI Chips & Chip Design | N15: 187.8 | O15: 2026-09-15 | P15: =COUNTIF('Full Log'!$A:$A,$A15) | Q15: 2026-08-18 | R15: 2026-09-15 | S15: 💡 CASH RECONCILES TO THREE CENTS ON 236,000 DOLLARS. The 11 September balance of 227,203.00, plus the four settlements forecast that day (+3,677.68), plus ZETA, QCOM and the dividend, gives 236,324.20 against the 236,324.23 POEMS shows. THE FORECAST MADE ON 11 SEPTEMBER WAS RIGHT. ⚠️ THURSDAY 17 SEPTEMBER COMMITS 46,526.13 OF IT to six tranches, leaving about 189,798.
A16: SNPS | B16: Synopsys | I16: AI Chips & Chip Design | M16: 13000 | N16: 367.7 | O16: 2026-09-15 | P16: =COUNTIF('Full Log'!$A:$A,$A16) | Q16: 2026-08-17 | R16: 2026-09-18 | S16: ACTION: WRITE THE ZERO-OIL DECISION DOWN - either a deliberate exclusion or an unintended gap. Either answer is fine; having no answer is the same absence-of-a-decision fault as ARM, SNPS, LHX, APP and SE.
A17: AMAT | B17: Applied Materials | C17: Equipment that deposits and etches the microscopic layers inside every chip. | D17: 1967 | E17: California, United States | F17: 36,500 | G17: Supplies chip factory equipment, services and software in the United States, China, Korea, Taiwan, Japan, Southeast Asia and Europe, through two business arms. | H17: To provide the equipment, services and know-how that chipmakers use to build semiconductors. | I17: Foundry, Equipment & Test | J17: YES | K17: 38 | L17: 10086.63 | M17: 22000 | N17: 417.4 | O17: 2026-09-17 | P17: =COUNTIF('Full Log'!$A:$A,$A17) | Q17: 2026-07-20 | R17: 2026-09-19 | S17: Why it inflected. On July 29 AXT signed a supply agreement with Lumentum — that's LITE, already in this same group — running to end-2031. Lumentum pays $43.5M up front and another $43.5M in 2028, $87M total, applied as credits against reserved wafer capacity. That is a customer pre-paying for years of flour. The very next day AXT reported Q2 with adjusted earnings of $0.19 against $0.07 expected — nearly triple. Gross margin jumped from the low-30s to 44.9%.
A18: AMKR | B18: Amkor Technology | C18: Packages and tests finished chips on behalf of other chip companies. | D18: 1968 | E18: Arizona, United States | F18: 30,800 | G18: Packages and tests finished chips for other companies, with operations in the United States, Japan, Europe and the Asia-Pacific region. | H18: To handle the final packaging and testing steps for chipmakers, device makers and factories that do not do this work themselves. | I18: Foundry, Equipment & Test | N18: 46.38 | O18: 2026-09-15 | P18: =COUNTIF('Full Log'!$A:$A,$A18) | Q18: 2026-07-21 | R18: 2026-09-18 | S18: Worth noting on the close: MU finished at $820.53, +35.89%, recovering above where it traded intraday — the market did not fully buy the CXMT supply-glut story. The real damage on the book is older wounds, not Jul 28: AMKR −27.26%, ORCL −27.85%, TSLA −28.58%.
A19: ASML | B19: ASML Holding | C19: The only company that makes the EUV machines needed for the most advanced chips. | D19: 1984 | E19: Netherlands | F19: 44,175 | G19: Sells, upgrades and services the machines that print circuit patterns onto chips, supporting chipmakers across Asia, Europe and North America. | H19: To provide the advanced printing, measuring and inspection machines that chipmakers need to produce semiconductors. | I19: Foundry, Equipment & Test | J19: YES | K19: 13 | L19: 16394.06 | M19: 41000 | N19: 1629.67 | O19: 2026-09-17 | P19: =COUNTIF('Full Log'!$A:$A,$A19) | Q19: 2026-07-22 | R19: 2026-09-19 | S19: One honest limitation. I can only use logos that come from an open, freely-licensed icon library that I can install into this workspace; I can't pull company logos off the internet from here, and most chip and industrial companies never released a free version of their mark. So nine of the twenty are the real brandmarks — NVDA, GOOGL, AMZN, MSFT, META, AVGO, AMD, AAPL and PANW. The other eleven — TSM, MU, ASML, AMAT, ANET, ISRG, CRDO, MRVL, ETN, CRWD and ORCL — get a ticker monogram in exactly the same gold-ringed disc.
A20: INTC | B20: Intel | C20: The historic US chipmaker, now rebuilding both its chip designs and its factories. | D20: 1968 | E20: California, United States | F20: 85,100 | G20: Designs and manufactures chips, with operations in the United States, Ireland and Israel, run as three units including a factory arm making chips for others. | H20: To design, make and sell computing products, and to build a manufacturing business that produces chips for other companies. | I20: Foundry, Equipment & Test | J20: YES | K20: 25 | L20: 1127.56 | N20: 108.8 | O20: 2026-09-17 | P20: =COUNTIF('Full Log'!$A:$A,$A20) | Q20: 2026-07-21 | R20: 2026-09-17 | S20: > Conviction: High. Horizon: Long (3–5 years, fits the 2030 mandate). What would change my mind: a serious Taiwan Strait escalation, or evidence that Intel or Samsung has genuinely closed the leading-edge manufacturing gap.
A21: KLAC | B21: KLA Corporation | C21: Inspection machines that find microscopic defects on chips during manufacturing. | D21: 1975 | E21: California, United States | F21: 15,200 | G21: Runs three business lines making inspection and measuring machines for chip and circuit-board plants, sold worldwide. | H21: Aims to help chip makers find and fix flaws early so more of what they build works properly. | I21: Foundry, Equipment & Test | J21: YES | K21: 18 | L21: 3510.69 | M21: 14000 | N21: 168.98 | O21: 2026-09-17 | P21: =COUNTIF('Full Log'!$A:$A,$A21) | Q21: 2026-07-22 | R21: 2026-09-18 | S21: Also, the Jul 31 earnings cron landed while the container was rolled back: AAPL, AMZN, COIN, MA, plus a KLAC catch-up. Two worth your attention — AMZN's $5.75 Q2 EPS includes a $53.4B pre-tax Anthropic mark-up, so the board stores underlying TTM EPS of 8.61 ex-gain; and COIN's TTM has turned loss-making, which nulled its P/E, forward P/E, PEG, EV/EBITDA and Rule-40.
A22: LRCX | B22: Lam Research | C22: Etching and deposition equipment, especially important for advanced memory chips. | D22: 1980 | E22: California, United States | F22: 17,200 | G22: Builds, services and refurbishes chip-making machines, selling into the United States, China, Korea, Taiwan, Japan, Southeast Asia and Europe. | H22: Aims to supply the machines that lay down, carve and clean the layers used to build computer chips. | I22: Foundry, Equipment & Test | J22: YES | K22: 22 | L22: 4100.12 | M22: 16000 | N22: 269.31 | O22: 2026-09-17 | P22: =COUNTIF('Full Log'!$A:$A,$A22) | Q22: 2026-07-20 | R22: 2026-09-19 | S22: I want to be fair to it, because it's the most interesting of the three rejects. AirJoule has a 50/50 joint venture with GE Vernova that is genuinely operating — they installed a unit at GE Vernova's research campus in New York on July 28. Kubota signed them as exclusive US residential partner on July 21 (the stock jumped 15% that day). They have $35M cash and no debt, funded into 2028. All five analysts covering it have targets above the current price — the lowest target, $6.00, sits above the $5.95 price.
A23: TER | B23: Teradyne | C23: Machines that test finished chips, plus industrial and collaborative robots. | D23: 1960 | E23: Massachusetts, United States | F23: 6,600 | G23: Designs and sells machines that test computer chips, and also makes robots, operating in the United States, Asia Pacific, Europe, the Middle East and Africa. | H23: To supply the testing equipment that checks chips work properly, plus robots that work alongside people in factories. | I23: Foundry, Equipment & Test | J23: YES | K23: 10 | L23: 3567.37 | N23: 353.13 | O23: 2026-09-17 | P23: =COUNTIF('Full Log'!$A:$A,$A23) | Q23: 2026-07-22 | R23: 2026-09-18 | S23: AEHR → move from Group 1 to Group 2. ⚠️ It's misfiled today. AEHR sits in *Computing Chips* but it doesn't make chips — it makes wafer-level burn-in and test *equipment*. It belongs in Group 2, Chips Manufacturing, alongside ASML, AMAT, LRCX and KLAC, which is exactly its peer set. While we're in there: TER (Teradyne) is also misfiled, sitting in Group 6 (Robotic/Automation/EV). Teradyne's revenue is overwhelmingly semiconductor test; the robotics arm is the minority. It should move to Group 2 as well, so all the semi-cap equipment sits together and dad can see his true test-and-tools exposure in one row.
A24: TSEM | B24: Tower Semiconductor | C24: Tower Semiconductor is a contract chip manufacturer - a foundry - but unlike the giants chasing the smallest, fastest digital chips, Tower specialises in analog and specialty chips: parts that handle radio signals, electrical power, light and sensing. Its customers are other chip companies and system makers who design the chips and pay Tower to build them, for use in mobile phones, data-centre optical networking gear, cars, industrial equipment and medical devices. | D24: 1993 | E24: Migdal Haemek, Israel | F24: 5,613 | G24: Runs wafer fabrication plants in Israel, the United States, Japan and Italy, and in July 2026 announced a roughly 3 billion dollar capacity expansion in Japan with Japanese government (METI) support. Q2 2026 revenue mix: RF Infrastructure 25 percent, RF Mobile 23 percent, Power 17 percent, Sensors and Displays 15 percent, Discrete 11 percent, mixed-signal/CMOS and other 9 percent. Listed on NASDAQ since October 1994 and dual-listed in Tel Aviv. | H24: To be the analog specialty foundry of choice, and in particular to become a leading supplier of silicon photonics for AI data centres - management has taken that business from a 180 million dollar annualised run rate in Q2 2025 to 680 million in Q2 2026, targets 1 billion annualised by Q4 2026, has 1.3 billion of signed silicon photonics contracts for 2027, and has raised its 2028 model to 3.6 billion of revenue which it describes as fully spoken for by customers. | I24: Foundry, Equipment & Test | N24: 195.12 | O24: 2026-09-15 | P24: =COUNTIF('Full Log'!$A:$A,$A24) | Q24: 2026-08-11 | R24: 2026-09-14 | S24: (5) DECISION: NO BUDGET CHANGES, NOTHING BOUGHT OR SOLD, GROUP 4 STAYS AT 83,000. CIEN IS TRACKED, NOT FUNDED. Conviction HIGH. ⚠️ WHAT WOULD CHANGE MY MIND ON CIEN: two consecutive quarters of revenue growth above 25% WITH GAAP operating margin holding above 15% - that would make it the only profitable pure optical-systems company on the board and worth displacing something for. ⚠️ AND THE HONEST CONSTRAINT REMAINS: THE BOARD IS FULL AT 1,000,000 ACROSS 37 FUNDED NAMES. Funding CIEN means trimming something, and that decision belongs at the 10 DECEMBER REVIEW with TSEM and AGLT, not today.
A25: TSM | B25: Taiwan Semiconductor | C25: The world's chip factory — actually manufactures the chips Nvidia, Apple and AMD design. | D25: 1987 | E25: Taiwan | F25: 90,557 | G25: Makes, packages and tests chips for other companies, selling in Taiwan, China, Europe, the Middle East, Africa, Japan and the United States. | H25: To manufacture the chips its customers design, for computing, phones, cars, connected devices and home electronics. | I25: Foundry, Equipment & Test | J25: YES | K25: 147.5 | L25: 54856.42 | M25: 74000 | N25: 430.26 | O25: 2026-09-17 | P25: =COUNTIF('Full Log'!$A:$A,$A25) | Q25: 2026-07-21 | R25: 2026-09-19 | S25: 2. A small commission quirk. For your TSM row, POEMS included the $8.56 commission in the cost figure. For today's two orders it didn't — the cost is exactly shares × price. That's almost certainly because they haven't settled yet. So each of those two cost bases may creep up by $8.56 in a later snapshot. Nothing to fix; just don't be surprised by it.
A26: MU | B26: Micron Technology | C26: Memory chips, including the high-speed HBM memory that feeds AI processors. | D26: 1978 | E26: Idaho, United States | F26: 53,000 | G26: Four business units making memory and storage chips, with sales in the US, Taiwan, Japan, mainland China, Hong Kong and Europe. | H26: Aims to make the memory and storage chips used in data centres, phones, cars and computers. | I26: Memory & Storage | J26: YES | K26: 35.45 | L26: 22581.58 | M26: 51000 | N26: 977.5 | O26: 2026-09-17 | P26: =COUNTIF('Full Log'!$A:$A,$A26) | Q26: 2026-07-20 | R26: 2026-09-18 | S26: It is genuinely at the cheap end of its own range. Meta at $582.61 sits near the bottom of where it has traded all year ($520 low, $796 high). Compare that to Micron, SanDisk and Lumentum, which after this morning are all in the upper half of their yearly range. You are buying low on this one and high on those.
A27: SKHY | B27: SK hynix (NASDAQ ADR, listed Jul 10 '26) | C27: Korean memory maker — the leading supplier of HBM memory used by AI chips. | D27: 1983 | E27: South Korea | F27: 47,639 | G27: Korean maker of memory and storage chips selling across Korea, China, the rest of Asia, the United States and Europe; also makes chips to order. | H27: Aims to supply memory and storage chips for servers, phones, computers and cars. | I27: Memory & Storage | J27: YES | K27: 15 | L27: 1913.26 | N27: 182.99 | O27: 2026-09-17 | P27: =COUNTIF('Full Log'!$A:$A,$A27) | Q27: 2026-07-21 | R27: 2026-09-17 | S27: Which leaves the Jul 28 anomaly unexplained: that run reached ARM, AEHR, SKHY, CRWV, NBIS and 53 others, all of which are denied today. The most likely explanation is that FMP tightened the Basic sample list sometime between Jul 28 and Jul 30 and your job was quietly caught by it. I can't prove that from outside, and it doesn't change what you should do — but I'm not going to pretend I have a clean account of it.
A28: SNDK | B28: SanDisk | C28: Flash memory and SSD storage, spun out of Western Digital. | D28: 2024 | E28: California, United States | F28: 11,000 | G28: Makes flash-memory drives and cards, selling in the US, Europe, the Middle East, Africa and Asia to computer makers, data centres and retailers. | H28: Aims to supply fast flash storage for computers, phones, cars and data centres. | I28: Memory & Storage | N28: 1530.9 | O28: 2026-09-15 | P28: =COUNTIF('Full Log'!$A:$A,$A28) | Q28: 2026-07-22 | R28: 2026-09-13 | S28: You are lowering the cost of something you already own and believe in. Your 56 Meta shares cost you $664 each and are showing a loss of about 11%. Adding at $582 brings that average down. That is very different from Lumentum or SanDisk, where you would be starting a fresh bet at the top of a news spike.
A29: STX | B29: Seagate Technology | C29: Hard disk drives — the bulk storage that fills data centres. | D29: 1978 | E29: Singapore | F29: 30,000 | G29: Supplies storage drives and systems from Singapore, the United States and the Netherlands, selling to equipment makers, distributors and retailers. | H29: Aims to provide the drives and systems that store the world's growing pile of data. | I29: Memory & Storage | N29: 771.81 | O29: 2026-09-15 | P29: =COUNTIF('Full Log'!$A:$A,$A29) | Q29: 2026-07-29 | R29: 2026-09-13 | S29: I caught this because when I pulled the full history tables for those names, the number stored on the board matched the Jul 29 row exactly, every single time. ARM 224.89, SNDK 1015.89, STX 764.43, DELL 369.64, and thirty-plus more.
A30: AAOI | B30: Applied Optoelectronics | C30: Optical transceivers that carry data as light inside data centres. | D30: 1997 | E30: Texas, United States | F30: 4,691 | G30: Designs and makes fibre-optic networking parts, with operations in the United States, Taiwan and China. | H30: Aims to supply the light-based parts that move data inside data centres and across cable and phone networks. | I30: Networking & Optical | N30: 95.29 | O30: 2026-09-15 | P30: =COUNTIF('Full Log'!$A:$A,$A30) | Q30: 2026-07-22 | R30: 2026-09-16 | S30: Why it inflected. On July 29 AXT signed a supply agreement with Lumentum — that's LITE, already in this same group — running to end-2031. Lumentum pays $43.5M up front and another $43.5M in 2028, $87M total, applied as credits against reserved wafer capacity. That is a customer pre-paying for years of flour. The very next day AXT reported Q2 with adjusted earnings of $0.19 against $0.07 expected — nearly triple. Gross margin jumped from the low-30s to 44.9%.
A31: ALAB | B31: Astera Labs | C31: Connectivity chips that link AI processors together at very high speed. | D31: 2017 | E31: California, United States | F31: 756 | G31: Small chip designer operating in the United States and Taiwan, selling to very large data-centre operators and equipment makers. | H31: Aims to move data quickly between the parts inside cloud and artificial-intelligence computers. | I31: Networking & Optical | J31: YES | K31: 15 | L31: 3805.47 | M31: 11000 | N31: 293.56 | O31: 2026-09-17 | P31: =COUNTIF('Full Log'!$A:$A,$A31) | Q31: 2026-07-21 | R31: 2026-09-17 | S31: One last flag: APH and LITE sit in the same dashboard group. Adding aggressively to both concentrates dad further into the interconnect layer, which already includes ANET, CRDO and ALAB. That's a fine theme — it's just no longer a diversifying one.
A32: ANET | B32: Arista Networks | C32: High-speed network switches that connect the servers in AI data centres. | D32: 2004 | E32: California, United States | F32: 5,115 | G32: Sells computer-network equipment and software across the Americas, Europe, the Middle East, Africa and Asia-Pacific, direct and through resellers. | H32: Aims to supply the networking gear that connects data centres, offices and cloud services. | I32: Networking & Optical | J32: YES | K32: 98 | L32: 15585.57 | M32: 25000 | N32: 199.53 | O32: 2026-09-17 | P32: =COUNTIF('Full Log'!$A:$A,$A32) | Q32: 2026-07-24 | R32: 2026-09-13 | S32: One last flag: APH and LITE sit in the same dashboard group. Adding aggressively to both concentrates dad further into the interconnect layer, which already includes ANET, CRDO and ALAB. That's a fine theme — it's just no longer a diversifying one.
A33: APH | B33: Amphenol | C33: Connectors and cables — the physical plumbing of all electronics. | D33: 1932 | E33: Connecticut, United States | F33: 170,000 | G33: Three segments making electrical, electronic and fibre-optic connectors, cables and sensors in the United States, China and other countries. | H33: Aims to supply the connectors and cables that join electronic equipment in cars, planes, phones and data centres. | I33: Networking & Optical | J33: YES | K33: 32 | L33: 2004.4 | M33: 15000 | N33: 78.37 | O33: 2026-09-17 | P33: =COUNTIF('Full Log'!$A:$A,$A33) | Q33: 2026-07-22 | R33: 2026-09-15 | S33: One loose end: APH still shows 16 shares, so the $148.50 limit either wasn't placed or hasn't filled. It's at $150.31 now, so that limit is still realistic if dad wants it — but it now competes with META for the same dollars, and META at 17.75x is the better use of $2,000 than APH at 29.8x forward.
A34: AXTI | B34: AXT Inc | C34: Grows the crystal wafers (indium phosphide) that optical components are built on. | D34: 1986 | E34: California, United States | F34: 1,541 | G34: Makes the wafer discs chips are built on, selling directly in the US, China and Europe and via agents in Japan, Taiwan and Korea. | H34: Aims to supply specialty base materials used in lasers, sensors, wireless devices and solar cells. | I34: Networking & Optical | N34: 57.7 | O34: 2026-09-15 | P34: =COUNTIF('Full Log'!$A:$A,$A34) | Q34: 2026-08-06 | R34: 2026-09-15 | S34: AEHR is a judgement call worth being clear about. Aehr makes the ovens, in effect — machines that stress-test chips while they're still on the wafer, before anyone slices them up. Historically most of its revenue came from silicon carbide chips for electric vehicles, which is why it was sitting in Chips Manufacturing. The newer and faster-growing part of the business is testing silicon-photonics and AI optical devices, which is presumably why you want it next to LITE, COHR, AAOI and now AXTI.
A35: CIEN | B35: Ciena | C35: Ciena — the laser equipment that pushes huge amounts of data down fibre-optic cables. | D35: 1992 | E35: Maryland, United States | F35: 9,080 | G35: Serves more than 1,700 customers across the Americas, Europe and Asia-Pacific, backed by 4,500+ research staff and 2,400+ patents. | H35: Aims to build adaptive networks that keep pace with exploding bandwidth demand and help customers thrive in the AI era. | I35: Networking & Optical | N35: 334.33 | O35: 2026-09-15 | P35: =COUNTIF('Full Log'!$A:$A,$A35) | Q35: 2026-08-10 | R35: 2026-09-14 | S35: (5) DECISION: NO BUDGET CHANGES, NOTHING BOUGHT OR SOLD, GROUP 4 STAYS AT 83,000. CIEN IS TRACKED, NOT FUNDED. Conviction HIGH. ⚠️ WHAT WOULD CHANGE MY MIND ON CIEN: two consecutive quarters of revenue growth above 25% WITH GAAP operating margin holding above 15% - that would make it the only profitable pure optical-systems company on the board and worth displacing something for. ⚠️ AND THE HONEST CONSTRAINT REMAINS: THE BOARD IS FULL AT 1,000,000 ACROSS 37 FUNDED NAMES. Funding CIEN means trimming something, and that decision belongs at the 10 DECEMBER REVIEW with TSEM and AGLT, not today.
A36: COHR | B36: Coherent | C36: Lasers and optical components for data centres and industrial use. | D36: 1971 | E36: Pennsylvania, United States | F36: 30,216 | G36: Three segments - networking, materials and lasers - making optical parts and laser systems for industry, communications and electronics worldwide. | H36: Aims to supply the light-based parts and laser machines used in factories, data centres and research. | I36: Networking & Optical | N36: 271.17 | O36: 2026-09-15 | P36: =COUNTIF('Full Log'!$A:$A,$A36) | Q36: 2026-08-05 | R36: 2026-09-16 | S36: So the label now describes where the growth is coming from, not where the money currently comes from. That's a defensible way to organise a watchlist — but keep in mind when you look at that group that AEHR's EV exposure hasn't disappeared, and the EV chip cycle has been weak. If silicon carbide demand stays soft, AEHR can go down while the rest of the photonics shelf goes up. It won't move in sympathy with its new neighbours the way LITE and COHR move with each other.
A37: CRDO | B37: Credo Technology | C37: High-speed cables and chips that move data inside AI server racks. | D37: 2008 | E37: Cayman Islands | F37: 807 | G37: Sells high-speed cables, optical modules and chips in the United States, Taiwan, mainland China and Hong Kong, and licenses its designs. | H37: Aims to move data quickly and reliably between machines in data centres. | I37: Networking & Optical | J37: YES | K37: 54 | L37: 7700.99 | M37: 18000 | N37: 168.25 | O37: 2026-09-17 | P37: =COUNTIF('Full Log'!$A:$A,$A37) | Q37: 2026-07-21 | R37: 2026-09-15 | S37: One last flag: APH and LITE sit in the same dashboard group. Adding aggressively to both concentrates dad further into the interconnect layer, which already includes ANET, CRDO and ALAB. That's a fine theme — it's just no longer a diversifying one.
A38: FN | B38: Fabrinet | C38: Contract manufacturer that builds optical modules for other companies. | D38: 1999 | E38: Cayman Islands | F38: 16,457 | G38: Contract manufacturer serving North America, Asia-Pacific and Europe, assembling optical and precision electronic products for other brands. | H38: Aims to build complex optical and electronic products for the companies that design them. | I38: Networking & Optical | N38: 380.92 | O38: 2026-09-17 | P38: =COUNTIF('Full Log'!$A:$A,$A38) | Q38: 2026-07-21 | R38: 2026-09-18 | S38: Portfolio now: $560,432 cost, $683,857 market value, +$123,426 (+22.02%). A strong day across the board — 109 of 112 names repriced, and the tone was risk-on: PLTR +29%, AAOI +19%, ARM +17%, FN +16%, your own AMD +7% and AVGO +6.6%.
A39: GLW | B39: Corning | C39: Corning — optical fibre for networks and the tough glass on phone screens. | D39: 1851 | E39: New York, United States | F39: 67,200 | G39: Five businesses - optical cable, display glass, specialty materials, car parts and lab products - operating across the US, Asia and Europe. | H39: Aims to use its glass and ceramics know-how to serve communications, screens, cars and laboratories. | I39: Networking & Optical | N39: 143.57 | O39: 2026-09-15 | P39: =COUNTIF('Full Log'!$A:$A,$A39) | Q39: 2026-07-21 | R39: 2026-09-15 | S39: $119.26, no budget/position, blank as requested. Fair warning on what the card will show you: this is a wild one — opened the year at $36.35 (+228% YTD even now), ran to a $233.67 high in May, and has since been cut in half. Street says $57.50 / $151.30 / $220 across 6 analysts (avg = +27% conviction). Revenue +51% YoY on the datacenter optics ramp, but it's burning cash hard — FCF −$449M against $507M of TTM revenue as it builds capacity, so no PE, and Rule of 40 is deeply negative on the FCF basis. It behaves more like a call option on 800G/1.6T transceiver share gains than like GLW or FN.
A40: LITE | B40: Lumentum | C40: Lasers and optical modules; a key supplier for AI data-centre networking. | D40: 2015 | E40: California, United States | F40: 10,562 | G40: Two segments, cloud and networking parts plus industrial lasers, selling across the Americas, Asia-Pacific, Europe, the Middle East and Africa. | H40: Aims to supply the light-based parts and lasers used in data centres, networks and factories. | I40: Networking & Optical | J40: YES | K40: 11.5 | L40: 9372.74 | M40: 14000 | N40: 893.61 | O40: 2026-09-17 | P40: =COUNTIF('Full Log'!$A:$A,$A40) | Q40: 2026-07-22 | R40: 2026-09-17 | S40: So the label now describes where the growth is coming from, not where the money currently comes from. That's a defensible way to organise a watchlist — but keep in mind when you look at that group that AEHR's EV exposure hasn't disappeared, and the EV chip cycle has been weak. If silicon carbide demand stays soft, AEHR can go down while the rest of the photonics shelf goes up. It won't move in sympathy with its new neighbours the way LITE and COHR move with each other.
...

Sheet Comment Log
A1: Ticker | B1: Week | C1: View | D1: Executive summary (green = positive, red = negative / risk)
A2: AMZN | B2: 2026-07-20 (Jul 20-26, 2026) | C2: MIXED | D2: + Advisor's runner-up buy: +26.9% to a 65-analyst target, cheapest of five candidates at 3.6x sales and 29.6x forward earnings; suggested GTC limit ~$246-248. Added 8 shares at $244.00 on Jul 22; now 202 shares at $46,595 cost, leaving $3,405 of the $50K plan. - Jul 30 earnings is the key risk: AWS growth below ~17% or a capex guide-down would break the thesis; ideal entry seen as after the print. FCF-based scoring deliberately harsh on AMZN (13.9) - it punishes mid-investment companies, so the metric looks worse than the business.
A3: AMZN | B3: 2026-07-27 (Jul 27 - Aug 02, 2026) | C3: MIXED | D3: RED FLAG: Q2 EPS of $5.75 includes a $53.4B pre-tax paper gain on the Anthropic stake; dashboard stores underlying TTM EPS of 8.61 ex-gain so the P/E isn't distorted. + Stock jumped 15% overnight after earnings, blowing straight through the standing buy limit. Post-earnings fundamentals refreshed on the dashboard at the Jul 30 close.
A4: AMZN | B4: 2026-08-03 (Aug 03-09, 2026) | C4: MIXED | D4: - Advisor pushed back on adding: least upside of ten names (+14.8% to target), only 2.5% below its 52-week high, 29.6x forward, 23% above Dad's limit - META preferred. + Robotics case: operating margin 11.4% to 13.7%; robot ~$3k/yr vs human ~$34k; 100 robotic centres in 18 months, 40% faster; Morgan Stanley sees up to $4B annual savings. Bought 7 shares at $285.36 on Aug 4 ($2,006 with fees); now 209 shares at avg cost $232.54, worth $59,360, +22.1%; sleeve essentially full with $1,399 left. - Watch item: if operating margin stalls below 14% next quarter despite the robot rollout, the savings are one-off, not structural.
A5: AMZN | B5: 2026-08-31 (Aug 31 - Sep 06, 2026) | C5: NEGATIVE | D5: R&D SPENDING ACROSS THE MEGA-CAPS, saved to notes at Salee's request from an Oxford Club graphic (Sep 5, 2026). Amazon's line: technology and infrastructure of $108,521M for FY2025, ended Dec 31 2025, up 22.6% from $88,544M in FY2024. Verified independently against Amazon's FY2025 10-K and its Q4 2025 earnings release on SEC EDGAR - both print the same figure. RED FLAG: ⚠️ AMAZON'S $108.5B IS NOT A RESEARCH NUMBER and must not be set beside the other six. Amazon reports no 'research and development' line at all - the tag does not even exist in its SEC XBRL data. 'Technology and infrastructure' is a wider bucket that also carries the running costs of AWS infrastructure. Amazon topping this chart is an artifact of how the line is drawn, not evidence that it out-researches Alphabet by 78%. Anyone quoting this as an R&D league table has the wrong end of it. Corrected ranking, latest reported fiscal year, US$ millions: AMZN 108,521 (+22.6%, technology & infrastructure, NOT R&D) - GOOGL 61,087 (+23.8%) - META 57,372 (+30.8%) - MSFT 35,562 (+9.5%) - AAPL 34,550 (+10.1%) - NVDA 18,497 (+43.2%) - TSLA 6,411 (+41.2%). The six genuine R&D lines total $213.5B. Fiscal calendars are not aligned: NVIDIA's year ended Jan 25 2026, Microsoft's Jun 30 2026, Apple's Sep 27 2025, and Amazon/Alphabet/Meta/Tesla Dec 31 2025 - so this is not a like-for-like comparison of the same twelve months. RED FLAG: ⚠️ THE SOURCE GRAPHIC IS A FULL YEAR STALE ON MICROSOFT. It printed $32.5B, +10.1% - that is Microsoft's fiscal 2025, ended Jun 30 2025. Fiscal 2026 ended Jun 30 2026 and the 10-K was filed Jul 29 2026, before the graphic's own stated 'as of Aug 2026' cutoff, so the current number was available and was not used. The true figure is $35,562M, +9.5%. That also flips the ranking: Microsoft is 4th, ahead of Apple's $34,550M, not 5th behind it. Six of the seven figures matched the SEC filings to the dollar; only Microsoft did not. Reading the growth rather than the level: Nvidia +43.2% and Tesla +41.2% are the fastest, but from small bases. In absolute dollars Meta added the most real research spend (+$13.5B) and Alphabet next (+$11.8B). Amazon's +$20.0B is the largest increase of all seven, but it is mostly infrastructure build - the same capex story already sitting in the AWS thesis, not incremental research. No board fields were changed by this entry; it is reference information only. (new, not yet condensed) Sep 5, 2026 - R&D SPENDING RECORDED FOR THE SEVEN MEGA-CAPS at Salee's request, saved to the per-stock notes page. Latest reported fiscal year, US$ millions, every figure independently verified against SEC filings: AMZN 108,521 (+22.6%) - GOOGL 61,087 (+23.8%) - META 57,372 (+30.8%) - MSFT 35,562 ... (new, not yet condensed) ⚠️ AMZN's 108,521 is its 'technology and infrastructure' line, not research and development. Amazon reports no R&D line at all - the tag does not exist in its SEC XBRL data - and that bucket also carries the running costs of AWS infrastructure. Amazon leading this chart is an artifact of how the ... (new, not yet condensed) WHERE THE REAL LINK IS: token consumption. Agents running 40-minute autonomous tasks burn far more tokens than chat, at 2.5x the price. That feeds inference silicon, memory, interconnect and power over 12-24 months - it does not show up in a two-day price move. Most direct listed beneficiaries in ...
A6: AMZN | B6: 2026-09-07 (Sep 07-13, 2026) | C6: NEUTRAL | D6: (new, not yet condensed) TIER 3 CONVICTION (+30,000, 10,000 each): AVGO 40,000 to 50,000, ASML 30,000 to 40,000, MU 30,000 to 40,000. ⚠️ AVGO now sits at 50,000 and therefore MOVES FROM TIER 3 TO TIER 2, joining GOOGL, TSM, MSFT, AMZN and META. ⚠️ AND THE HONEST CAVEAT: these three already had 30,899.18 of budget they have ... (new, not yet condensed) Corrected trailing net income: GOOGL 244.1bn, NVDA 192.9bn, AMZN 135.3bn, MSFT 133.7bn, AAPL 128.9bn, BRK 85.8bn, META 68.1bn. NVDA's graphic figure of 120.07bn was 61% too low and seven months stale - one recent quarter alone (59.7bn) is half that whole 'year'. (new, not yet condensed) But the corrected ranking has its own trap: GOOGL's lead rests on a disclosed 77.1bn after-tax unrealised equity gain and AMZN's on 53.4bn of pre-tax other income from Anthropic. On operating earnings NVDA is the most profitable business in America. (new, not yet condensed) AMZN IS FULL AND STOPS HERE: 48,600 invested against a 48,000 target. The business is not the problem - Q2 2026 net sales +20% to 200.6bn, AWS +37% to 42.2bn at a 39.4% operating margin, consolidated operating income 27.5bn. The CASH is the problem: Amazon's own reconciliation reads 'Free cash flow ...
A7: AMZN | B7: 2026-09-14 (Sep 14-20, 2026) | C7: MIXED | D7: - ⚠️⚠️ THE FIRST TRUE BUDGET BREACH THIS BOARD HAS EVER HAD, FOUND 16 SEPTEMBER. AMAZON HAS 48,600.75 INVESTED ACROSS 209 SHARES AGAINST AN APPROVED BUDGET OF 48,000.00 - OVER BY 600.75, OR 1.25%. It is the ONLY name in ninety-four where money SPENT exceeds money APPROVED. || ⚠️ THIS IS A WORSE CLASS OF FAULT THAN THE THREE FOUND EARLIER TODAY. The MRVL 4,000, the GOOGL 2,000 and the Micron 11,000 were PROMISES that exceeded or lacked a budget - not yet spent, fixable with a keystroke. THIS ONE IS ALREADY SPENT; the shares are bought. || The size looks like commission plus the gap between a planned amount and an actual fill price on the last tranche, but NO SOURCED CAUSE FOUND and I will not record a guess as a cause. Amazon has NO remaining schedule rows, so the breach cannot widen. || ⚠️ I HAVE DELIBERATELY NOT FIXED IT. Raising the budget to 48,600.75 breaks the board's hardest constraint - that all budgets sum to exactly 1,000,000 - unless 600.75 is taken from another name, and quietly moving approved money to tidy a rounding error is how a budget stops meaning anything. TWO HONEST OPTIONS ON 10 DECEMBER: (A) raise Amazon and take 600.75 from an unspent budget elsewhere, or (B) WRITE A TOLERANCE RULE - 2% or 1,000, whichever is smaller - permitting commission and fill drift. I FAVOUR (B): the alternative is re-cutting budgets every time a fill comes in a few cents high. RED FLAG: ⚠️⚠️ THE DISCLOSURE ITEM THAT MATTERS MORE THAN ANY COMPUTE HEADLINE, AND IT IS IN AMAZON'S OWN FILING. THE Q2 2026 EARNINGS RELEASE STATES VERBATIM: 'Second quarter 2026 net income includes non-operating pre-tax other income of $53.4 billion, primarily from our investments in Anthropic.' AGAINST OPERATING INCOME OF 27.5 BILLION. ⚠️ THE MARK ON A PRIVATE COMPANY WAS ROUGHLY TWICE THE ENTIRE OPERATING PROFIT OF AMAZON. The 10-Q shows 8.0bn invested from Q3 2023 to Q4 2025, carried at about 74.2bn at 31 March 2026, with 39.5bn of unrealised gain sitting in AOCI. ⚠️⚠️ CONFLICT DISCLOSED: ANTHROPIC MAKES ME, AND I WILL NOT OFFER A VIEW ON WHETHER THAT VALUATION IS RIGHT. || WHAT I CAN SAY IS WHAT IT MEANS FOR READING THE ACCOUNTS: WHEN A MARK ON ONE PRIVATE HOLDING IS TWICE OPERATING PROFIT, THE HEADLINE EPS IS NOT TELLING YOU ABOUT THE RETAIL AND CLOUD BUSINESS. AWS segment sales grew 37% to 42.2bn - THAT is the number to judge Amazon on. Amazon also guides CY2026 capex to 220bn, raised from 200bn. RED FLAG: ⚠️ AMAZON'S Q2 2026 NET INCOME OF 62,647 MILLION IS NOT MOSTLY OPERATING PROFIT. From its own release, verbatim: 'Second quarter 2026 net income includes NON-OPERATING PRE-TAX OTHER INCOME OF 53.4 BILLION, PRIMARILY FROM OUR INVESTMENTS IN ANTHROPIC.' ⚠️⚠️ I HAVE A DISCLOSED CONFLICT REGARDING ANTHROPIC - it is on file in this project. I report Amazon's own disclosure as written and take NO view on the valuation behind it; if this item ever drives a decision, Salee should ask someone with no stake. ⚠️ SET BESIDE THE OTHER AMAZON FACT ALREADY ON THIS BOARD: trailing-twelve-month FREE CASH FLOW IS NEGATIVE 7.6 BILLION. Record accounting profit and negative cash generation in the same company, in the same period. CASH DOES NOT LIE; NET INCOME CAN. Trailing-twelve-month GAAP net income is 135,281m, which would rank Amazon THIRD in America - not fifth as the circulating slide shows, because that slide uses Amazon's calendar 2025 figure of 77,670m. Budget unchanged at 48,000. RED FLAG: ⚠️ TRAILING-TWELVE-MONTH FREE CASH FLOW IS NOW NEGATIVE 7.6 BILLION, against POSITIVE 18.2 BILLION a year earlier - stated in Amazon's own Q2 2026 release. Operating cash flow was 161.4bn, up 33%, but purchases of property and equipment were 169.0bn. AND IT ISSUED 67.0 BILLION OF LONG-TERM DEBT IN THE FIRST HALF OF 2026 ALONE, taking long-term debt to 128.9bn. CFO Brian Olsavsky, verbatim, 30 July: 'You've seen us issue debt this year. We have a lot of options available to us as we continue to fund this growth.' ⚠️ THE CLAIM THAT AI CAPEX IS FUNDED FROM CASH FLOW RATHER THAN DEBT IS NO LONGER TRUE HERE. Guidance is about 220bn of cash capex in 2026, raised from about 200bn because of memory costs. + IN AMAZON'S FAVOUR ON THE HONESTY QUESTION: it is the only hyperscaler to SHORTEN depreciation life, cutting a subset of servers from SIX YEARS TO FIVE effective 1 Jan 2025, and saying why in its own 10-K: 'The shorter useful lives are due to the increased pace of technology development, particularly in the area of artificial intelligence and machine learning.' CEO Andy Jassy, 30 July 2026: 'The servers currently have a useful life of at least five to six years, and most of our AI capacity these days is being contracted for at least five-year terms.' Meta went the OTHER way with the same hardware. (new, not yet condensed) (5) WHAT CHANGES FOR US: NOTHING. NO BUDGET MOVES, NOTHING IS BOUGHT OR SOLD. Five of the seven are already core funded holdings - MSFT 58,000, GOOGL 78,000, NVDA 95,000, AAPL 24,000, AMZN 48,000, META 52,000, which is 355,000 of the 1,000,000 board in six of these seven names. Berkshire is not on ... (new, not yet condensed) ⚠️ WHAT ACTUALLY MATTERS TO US IS THE PUBLIC COUNTERPARTIES, AND HERE THE FINDINGS ARE REAL AND UNCOMFORTABLE. AMAZON'S Q2 2026 EARNINGS RELEASE DISCLOSES 53.4 BILLION OF NON-OPERATING PRE-TAX INCOME 'PRIMARILY FROM OUR INVESTMENTS IN ANTHROPIC' AGAINST OPERATING INCOME OF 27.5 BILLION - THE MARK ... (new, not yet condensed) 💡 SO WHAT DO WE OWN? THE INCUMBENT BEING ATTACKED (NVDA). THE WEAPON BEING USED AGAINST IT (AVGO 30,125.18 AND MRVL 7,872.66). ALL FOUR ATTACKERS (GOOGL, AMZN, MSFT, META - 200,195.14 BETWEEN THEM). AND THE GROUND THEY FIGHT ON (TSMC MAKES EVERY ONE OF THESE CHIPS WHOEVER DESIGNS THEM; MICRON SELLS ... (new, not yet condensed) 4. THE MAGNIFICENT-7 CASH CHART. ⚠️ APPLE IS NOT CASH-POOR AND THE CHART MEASURED THE WRONG LINE. Apple holds $146,517m of cash and marketable securities - SECOND OF THE SEVEN, not fifth - because $84,118m of it sits in LONG-TERM marketable securities that cash charts drop. Apple also returned ...
A8: GOOGL | B8: 2026-07-20 (Jul 20-26, 2026) | C8: MIXED | D8: + GOOGL is the book's quiet leader: +$15.6K of gain, more than the other six big holdings combined; only 13% off its high after a +12% YTD run - consolidation, not collapse. - Q2 (Jul 22) beat on headlines but free cash flow turned negative - capex outran $39.1B operating cash flow, $49.6B raised issuing equity; stock fell ~5-6% to the low $340s. - Capex is running ~42% of revenue and P/FCF is 72.5 and climbing; the fortress balance sheet (D/E 0.18) can afford it, but you are paying up while cash flow is impaired. + Bought the dip: +7 shares at ~$319.38 ($2,235.64) - now 205 shares at $269.88 avg cost, +17.7% unrealized; right instinct on a compounder whose Cloud is growing 82%. - Discipline flag: Dad's written limit was under $300 and the fill was $319, about 6% above the plan; the real add sits near $300 if the capex selloff continues. Weekly revision scan showed the Street's average GOOGL target drifting down 3.3%.
A9: GOOGL | B9: 2026-07-27 (Jul 27 - Aug 02, 2026) | C9: NEUTRAL | D9: Price could not be pinned down: a secondary page's $349.01 was distrusted after similar pages served stale data; the main page showed the Jul 30 close of $333.66.
A10: GOOGL | B10: 2026-08-03 (Aug 03-09, 2026) | C10: MIXED | D10: - Verdict: skip for now - GOOGL (with AMZN and MSFT) is 23-33% above Dad's limits with the smallest upside of the group. + Ranked #2 on the AI-beneficiary list: 8x engineering speed and falling AI serving cost (CEO-stated), $356.13 at Jul 31, 28.0x earnings, +20% upside, high confidence. Broker screen validated as a price source: POEMS 'Current Price' for GOOGL ($373.51, Aug 3) matched the official close to the cent.
A11: GOOGL | B11: 2026-08-10 (Aug 10-16, 2026) | C11: NEUTRAL | D11: (new, not yet condensed) Aug 11, 2026 · close — daily price refresh (run Aug 12, 00:30 UTC): 150 of 161 names advanced to the verified Aug 11 close (VECO was deleted upstream mid-run; its fetched close 50.16 discarded). Method per README: at-close quote pages with prev-close chain validated against history tables; ~20 ...
A12: GOOGL | B12: 2026-08-17 (Aug 17-23, 2026) | C12: NEUTRAL | D12: (new, not yet condensed) Aug 19, 2026 - close. CDNS and SNPS MOVED from SaaS to Computing Chips and placed side by side at the end of that group; both keep their existing prices, positions and budgets (CDNS 6 sh / 2,007.28 cost / 5,000 budget at the Aug 19 close of 314.98; SNPS watchlist-only at its Aug 17 price of ... (new, not yet condensed) Aug 19, 2026 - close. AEHR REPRICED from a stale Aug 17 quote of 145.61 to its verified Aug 19 close of 107.96 (-25.85% over two sessions: -15.36% Aug 18, -12.41% Aug 19). It closed 0.5% off the day's low on 2.9M shares - a full-day liquidation with no bounce - and 24/7 Wall St reported verbatim ... (new, not yet condensed) Aug 19, 2026 - close. CDNS BUDGET RAISED 5,000 -> 10,000 as instructed; at a cost of 2,007.28 that takes utilisation from 40.1% to 20.1% and headroom from 2,992.72 to 7,992.72. ALPHABET WAS NOT CHANGED: the instruction was to raise it TO 60,000 and it was ALREADY exactly 60,000, so there was ... (new, not yet condensed) Aug 19, 2026 - close. ALPHABET BUDGET RAISED 60,000 -> 70,000. At 59,475.92 of cost that takes utilisation from 99.1% to 84.97% and headroom from 524.08 to 10,524.08 - about 30 shares of room at the Aug 19 close of 344.72. GOOGL is 217 shares and 10.9% of the 686,813.04 book by market value; ... (new, not yet condensed) Aug 20, 2026 - close. BUDGET FIELDS RECONCILED - the last open item from the Aug 20 budget work. ORCL is CONFIRMED BY THE USER at 10,000, which is what the authoritative POS row already carried, so the dashboard was rendering it correctly all along; only the stale STOCKS mirror said 5,000 and it is ... (new, not yet condensed) Aug 20, 2026 - close. THREE CONVICTION BUDGETS RAISED to fund a staged 3-month programme: NVDA 80,000 -> 85,000 (+5,000), Alphabet 70,000 -> 80,000 (+10,000), TSM 50,000 -> 65,000 (+15,000). Headroom goes NVDA 2,659.04 -> 7,659.04, GOOGL 10,524.08 -> 20,524.08, TSM 10,078.47 -> 25,078.47. THE SKEW ...
